Workbook

Sheet Ingreso Datos
K1: 16 PF 5 | BY1: . | BZ1: . | CA1: .
A2: NOMBRE: | D2: aabr | L2: SEXO: | N2: F | S2: FECHA: | U2: 44792 | Y2: ESC. | Z2: PD | AA2: F | AB2: M | AC2: DE
A3: 1 | B3: 3 | C3: 17 | D3: 3 | E3: 33 | F3: 1 | G3: 49 | H3: 1 | I3: 65 | J3: 1 | K3: 81 | L3: 3 | M3: 97 | N3: 1 | O3: 113 | P3: 1 | Q3: 129 | R3: 1 | S3: 145 | T3: 3 | U3: 161 | V3: 1 | W3: 171 | X3: 2 | Y3: A | Z3: =(IF(B3>0,B3-1))+(IF(J3>0,J3-1))+(IF(H17>0,H17-1))+(IF(N4>0,N4-1))+(IF(R3>0,R3-1))+(IF(D17>0,(D17-3)*-1))+(IF(F3>0,(F3-3)*-1))+(IF(L18>0,(L18-3)*-1))+(IF(P17>0,(P17-3)*-1))+(IF(T17>0,(T17-3)*-1))+(IF(V3>0,(V3-3)*-1)) -> 16 | AA3: =VLOOKUP(Z3,'Tabla Mujeres'!$B$7:$C$29,2,FALSE) -> 5 | AB3: =VLOOKUP(Z3,'Tabla Varones'!$B$7:$C$29,2,FALSE) -> 6 | AC3: =IF($N$2="F",AA3,AB3) -> 5
A4: 2 | B4: 1 | C4: 18 | D4: 1 | E4: 34 | F4: 1 | G4: 50 | H4: 3 | I4: 66 | J4: 3 | K4: 82 | L4: 3 | M4: 98 | N4: 3 | O4: 114 | P4: 1 | Q4: 130 | R4: 1 | S4: 146 | T4: 3 | U4: 162 | V4: 3 | W4: 172 | X4: 2 | Y4: B | Z4: =(IF(X3=1,1))+(IF(X4=3,1))+(IF(X5=1,1))+(IF(X6=1,1))+(IF(X7=3,1))+(IF(X8=1,1))+(IF(X9=2,1))+(IF(X10=3,1))+(IF(X11=3,1))+(IF(X12=3,1))+(IF(X13=2,1))+(IF(X14=2,1))+(IF(X15=2,1))+(IF(X16=2,1))+(IF(X17=2,1)) -> 7 | AA4: =VLOOKUP(Z4,'Tabla Mujeres'!$D$7:$E$22,2,FALSE) -> 3 | AB4: =VLOOKUP(Z4,'Tabla Varones'!$D$7:$E$22,2,FALSE) -> 4 | AC4: =IF($N$2="F",AA4,AB4) -> 3
A5: 3 | B5: 3 | C5: 19 | D5: 3 | E5: 35 | F5: 3 | G5: 51 | H5: 1 | I5: 67 | J5: 1 | K5: 83 | L5: 1 | M5: 99 | N5: 1 | O5: 115 | P5: 1 | Q5: 131 | R5: 3 | S5: 147 | T5: 3 | U5: 163 | V5: 1 | W5: 173 | X5: 1 | Y5: C | Z5: =(IF(D18>0,D18-1))+(IF(F5>0,F5-1))+(IF(J5>0,J5-1))+(IF(R5>0,R5-1))+(IF(B4>0,(B4-3)*-1))+(IF(H18>0,(H18-3)*-1))+(IF(N3>0,(N3-3)*-1))+(IF(P18>0,(P18-3)*-1))+(IF(T18>0,(T18-3)*-1))+(IF(V4>0,(V4-3)*-1)) -> 10 | AA5: =VLOOKUP(Z5,'Tabla Mujeres'!$F$7:$G$27,2,FALSE) -> 4 | AB5: =VLOOKUP(Z5,'Tabla Varones'!$F$7:$G$27,2,FALSE) -> 3 | AC5: =IF($N$2="F",AA5,AB5) -> 4
A6: 4 | B6: 3 | C6: 20 | D6: 1 | E6: 36 | F6: 1 | G6: 52 | H6: 3 | I6: 68 | J6: 3 | K6: 84 | L6: 3 | M6: 100 | N6: 1 | O6: 116 | P6: 1 | Q6: 132 | R6: 1 | S6: 148 | T6: 1 | U6: 164 | V6: 1 | W6: 174 | X6: 2 | Y6: E | Z6: =(IF(N8>0,N8-1))+(IF(V5>0,V5-1))+(IF(B5>0,(B5-3)*-1))+(IF(F6>0,(F6-3)*-1))+(IF(F8>0,(F8-3)*-1))+(IF(J4>0,(J4-3)*-1))+(IF(N5>0,(N5-3)*-1))+(IF(R4>0,(R4-3)*-1))+(IF(R6>0,(R6-3)*-1))+(IF(V7>0,(V7-3)*-1)) -> 8 | AA6: =VLOOKUP(Z6,'Tabla Mujeres'!$H$7:$I$27,2,FALSE) -> 3 | AB6: =VLOOKUP(Z6,'Tabla Varones'!$H$7:$I$27,2,FALSE) -> 2 | AC6: =IF($N$2="F",AA6,AB6) -> 3
A7: 5 | B7: 1 | C7: 21 | D7: 1 | E7: 37 | F7: 1 | G7: 53 | H7: 3 | I7: 69 | J7: 1 | K7: 85 | L7: 1 | M7: 101 | N7: 1 | O7: 117 | P7: 1 | Q7: 133 | R7: 3 | S7: 149 | T7: 1 | U7: 165 | V7: 3 | W7: 175 | X7: 3 | Y7: F | Z7: =(IF(B8>0,B8-1))+(IF(F7>0,F7-1))+(IF(J8>0,J8-1))+(IF(V6>0,V6-1))+(IF(B6>0,(B6-3)*-1))+(IF(F9>0,(F9-3)*-1))+(IF(J6>0,(J6-3)*-1))+(IF(N6>0,(N6-3)*-1))+(IF(N9>0,(N9-3)*-1))+(IF(R8>0,(R8-3)*-1)) -> 10 | AA7: =VLOOKUP(Z7,'Tabla Mujeres'!$J$7:$K$27,2,FALSE) -> 4 | AB7: =VLOOKUP(Z7,'Tabla Varones'!$J$7:$K$27,2,FALSE) -> 4 | AC7: =IF($N$2="F",AA7,AB7) -> 4
A8: 6 | B8: 3 | C8: 22 | D8: 3 | E8: 38 | F8: 3 | G8: 54 | H8: 3 | I8: 70 | J8: 1 | K8: 86 | L8: 3 | M8: 102 | N8: 1 | O8: 118 | P8: 1 | Q8: 134 | R8: 1 | S8: 150 | T8: 1 | U8: 166 | V8: 1 | W8: 176 | X8: 3 | Y8: G | Z8: =(IF(J10>0,J10-1))+(IF(N12>0,N12-1))+(IF(R7>0,R7-1))+(IF(R10>0,R10-1))+(IF(V8>0,V8-1))+(IF(B7>0,(B7-3)*-1))+(IF(B9>0,(B9-3)*-1))+(IF(F10>0,(F10-3)*-1))+(IF(J7>0,(J7-3)*-1))+(IF(N10>0,(N10-3)*-1))+(IF(V10>0,(V10-3)*-1)) -> 20 | AA8: =VLOOKUP(Z8,'Tabla Mujeres'!$L$7:$M$29,2,FALSE) -> 8 | AB8: =VLOOKUP(Z8,'Tabla Varones'!$L$7:$M$29,2,FALSE) -> 7 | AC8: =IF($N$2="F",AA8,AB8) -> 8
A9: 7 | B9: 1 | C9: 23 | D9: 1 | E9: 39 | F9: 1 | G9: 55 | H9: 1 | I9: 71 | J9: 1 | K9: 87 | L9: 1 | M9: 103 | N9: 1 | O9: 119 | P9: 3 | Q9: 135 | R9: 3 | S9: 151 | T9: 1 | U9: 167 | V9: 1 | W9: 177 | X9: 2 | Y9: H | Z9: =(IF(F11>0,F11-1))+(IF(J9>0,J9-1))+(IF(N11>0,N11-1))+(IF(N13>0,N13-1))+(IF(V9>0,V9-1))+(IF(V11>0,V11-1))+(IF(B11>0,(B11-3)*-1))+(IF(J11>0,(J11-3)*-1))+(IF(R9>0,(R9-3)*-1))+(IF(R11>0,(R11-3)*-1)) -> 2 | AA9: =VLOOKUP(Z9,'Tabla Mujeres'!$N$7:$O$27,2,FALSE) -> 3 | AB9: =VLOOKUP(Z9,'Tabla Varones'!$N$7:$O$27,2,FALSE) -> 2 | AC9: =IF($N$2="F",AA9,AB9) -> 3
A10: 8 | B10: 2 | C10: 24 | D10: 1 | E10: 40 | F10: 1 | G10: 56 | H10: 1 | I10: 72 | J10: 3 | K10: 88 | L10: 3 | M10: 104 | N10: 1 | O10: 120 | P10: 2 | Q10: 136 | R10: 3 | S10: 152 | T10: 1 | U10: 168 | V10: 1 | W10: 178 | X10: 3 | Y10: I | Z10: =(IF(B8>0,B10-1))+(IF(N16>0,N16-1))+(IF(R12>0,R12-1))+(IF(R14>0,R14-1))+(IF(V12>0,V12-1))+(IF(B12>0,(B12-3)*-1))+(IF(F12>0,(F12-3)*-1))+(IF(F14>0,(F14-3)*-1))+(IF(J12>0,(J12-3)*-1))+(IF(J15>0,(J15-3)*-1))+(IF(N14>0,(N14-3)*-1)) -> 9 | AA10: =VLOOKUP(Z10,'Tabla Mujeres'!$P$7:$Q$29,2,FALSE) -> 4 | AB10: =VLOOKUP(Z10,'Tabla Varones'!$P$7:$Q$29,2,FALSE) -> 6 | AC10: =IF($N$2="F",AA10,AB10) -> 4
A11: 9 | B11: 1 | C11: 25 | D11: 3 | E11: 41 | F11: 1 | G11: 57 | H11: 1 | I11: 73 | J11: 3 | K11: 89 | L11: 1 | M11: 105 | N11: 1 | O11: 121 | P11: 3 | Q11: 137 | R11: 3 | S11: 153 | T11: 1 | U11: 169 | V11: 1 | W11: 179 | X11: 3 | Y11: L | Z11: =(IF(F15>0,F15-1))+(IF(J16>0,J16-1))+(IF(N15>0,N15-1))+(IF(R13>0,R13-1))+(IF(B13>0,(B13-3)*-1))+(IF(B15>0,(B15-3)*-1))+(IF(F13>0,(F13-3)*-1))+(IF(J14>0,(J14-3)*-1))+(IF(N18>0,(N18-3)*-1))+(IF(R15>0,(R15-3)*-1)) -> 16 | AA11: =VLOOKUP(Z11,'Tabla Mujeres'!$R$7:$S$27,2,FALSE) -> 7 | AB11: =VLOOKUP(Z11,'Tabla Varones'!$R$7:$S$27,2,FALSE) -> 8 | AC11: =IF($N$2="F",AA11,AB11) -> 7
A12: 10 | B12: 1 | C12: 26 | D12: 3 | E12: 42 | F12: 3 | G12: 58 | H12: 3 | I12: 74 | J12: 3 | K12: 90 | L12: 3 | M12: 106 | N12: 3 | O12: 122 | P12: 3 | Q12: 138 | R12: 1 | S12: 154 | T12: 3 | U12: 170 | V12: 1 | W12: 180 | X12: 3 | Y12: M | Z12: =(IF(D3>0,D3-1))+(IF(F16>0,F16-1))+(IF(H3>0,H3-1))+(IF(L3>0,L3-1))+(IF(P4>0,P4-1))+(IF(B14>0,(B14-3)*-1))+(IF(B16>0,(B16-3)*-1))+(IF(J17>0,(J17-3)*-1))+(IF(N17>0,(N17-3)*-1))+(IF(R16>0,(R16-3)*-1))+(IF(T3>0,(T3-3)*-1)) -> 12 | AA12: =VLOOKUP(Z12,'Tabla Mujeres'!$T$7:$U$29,2,FALSE) -> 7 | AB12: =VLOOKUP(Z12,'Tabla Varones'!$T$7:$U$29,2,FALSE) -> 8 | AC12: =IF($N$2="F",AA12,AB12) -> 7
A13: 11 | B13: 1 | C13: 27 | D13: 3 | E13: 43 | F13: 1 | G13: 59 | H13: 1 | I13: 75 | J13: 1 | K13: 91 | L13: 1 | M13: 107 | N13: 1 | O13: 123 | P13: 3 | Q13: 139 | R13: 1 | S13: 155 | T13: 3 | V13: 3 | W13: 181 | X13: 3 | Y13: N | Z13: =(IF(B17>0,B17-1))+(IF(D4>0,D4-1))+(IF(L6>0,L6-1))+(IF(P7>0,P7-1))+(IF(F17>0,(F17-3)*-1))+(IF(H4>0,(H4-3)*-1))+(IF(J18>0,(J18-3)*-1))+(IF(P3>0,(P3-3)*-1))+(IF(R17>0,(R17-3)*-1))+(IF(T6>0,(T6-3)*-1)) -> 12 | AA13: =VLOOKUP(Z13,'Tabla Mujeres'!$V$7:$W$27,2,FALSE) -> 6 | AB13: =VLOOKUP(Z13,'Tabla Varones'!$V$7:$W$27,2,FALSE) -> 6 | AC13: =IF($N$2="F",AA13,AB13) -> 6
A14: 12 | B14: 3 | C14: 28 | D14: 3 | E14: 44 | F14: 1 | G14: 60 | H14: 1 | I14: 76 | J14: 3 | K14: 92 | L14: 3 | M14: 108 | N14: 3 | O14: 124 | P14: 1 | Q14: 140 | R14: 1 | S14: 156 | T14: 3 | V14: 1 | W14: 182 | X14: 2 | Y14: O | Z14: =(IF(D5>0,D5-1))+(IF(D7>0,D7-1))+(IF(L4>0,L4-1))+(IF(P9>0,P9-1))+(IF(H5>0,(H5-3)*-1))+(IF(H8>0,(H8-3)*-1))+(IF(L9>0,(L9-3)*-1))+(IF(P6>0,(P6-3)*-1))+(IF(T4>0,(T4-3)*-1))+(IF(T8>0,(T8-3)*-1)) -> 14 | AA14: =VLOOKUP(Z14,'Tabla Mujeres'!$X$7:$Y$27,2,FALSE) -> 6 | AB14: =VLOOKUP(Z14,'Tabla Varones'!$X$7:$Y$27,2,FALSE) -> 7 | AC14: =IF($N$2="F",AA14,AB14) -> 6
A15: 13 | B15: 1 | C15: 29 | D15: 3 | E15: 45 | F15: 3 | G15: 61 | H15: 3 | I15: 77 | J15: 1 | K15: 93 | L15: 1 | M15: 109 | N15: 3 | O15: 125 | P15: 1 | Q15: 141 | R15: 1 | S15: 157 | T15: 3 | V15: 3 | W15: 183 | X15: 3 | Y15: Q1 | Z15: =(IF(D10>0,D10-1))+(IF(H6>0,H6-1))+(IF(H9>0,H9-1))+(IF(L8>0,L8-1))+(IF(T5>0,T5-1))+(IF(T9>0,T9-1))+(IF(D6>0,(D6-3)*-1))+(IF(D8>0,(D8-3)*-1))+(IF(H7>0,(H7-3)*-1))+(IF(L5>0,(L5-3)*-1))+(IF(L10>0,(L10-3)*-1))+(IF(P8>0,(P8-3)*-1))+(IF(P10>0,(P10-3)*-1))+(IF(T7>0,(T7-3)*-1)) -> 15 | AA15: =VLOOKUP(Z15,'Tabla Mujeres'!$Z$7:$AA$35,2,FALSE) -> 5 | AB15: =VLOOKUP(Z15,'Tabla Varones'!$Z$7:$AA$35,2,FALSE) -> 6 | AC15: =IF($N$2="F",AA15,AB15) -> 5
A16: 14 | B16: 3 | C16: 30 | D16: 2 | E16: 46 | F16: 3 | G16: 62 | H16: 1 | I16: 78 | J16: 3 | K16: 94 | L16: 1 | M16: 110 | N16: 3 | O16: 126 | P16: 3 | Q16: 142 | R16: 1 | S16: 158 | T16: 1 | W16: 184 | X16: 1 | Y16: Q2 | Z16: =(IF(D11>0,D11-1))+(IF(H10>0,H10-1))+(IF(L14>0,L14-1))+(IF(P13>0,P13-1))+(IF(T14>0,T14-1))+(IF(D13>0,(D13-3)*-1))+(IF(H13>0,(H13-3)*-1))+(IF(L11>0,(L11-3)*-1))+(IF(P11>0,(P11-3)*-1))+(IF(T10>0,(T10-3)*-1)) -> 14 | AA16: =VLOOKUP(Z16,'Tabla Mujeres'!$AB$7:$AC$27,2,FALSE) -> 9 | AB16: =VLOOKUP(Z16,'Tabla Varones'!$AB$7:$AC$27,2,FALSE) -> 9 | AC16: =IF($N$2="F",AA16,AB16) -> 9
A17: 15 | B17: 1 | C17: 31 | D17: 1 | E17: 47 | F17: 1 | G17: 63 | H17: 3 | I17: 79 | J17: 1 | K17: 95 | L17: 3 | M17: 111 | N17: 1 | O17: 127 | P17: 1 | Q17: 143 | R17: 1 | S17: 159 | T17: 3 | U17: 3 | W17: 185 | Y17: Q3 | Z17: =(IF(D12>0,D12-1))+(IF(D15>0,D15-1))+(IF(H11>0,H11-1))+(IF(L12>0,L12-1))+(IF(P12>0,P12-1))+(IF(T12>0,T12-1))+(IF(H15>0,(H15-3)*-1))+(IF(L15>0,(L15-3)*-1))+(IF(P15>0,(P15-3)*-1))+(IF(T15>0,(T15-3)*-1)) -> 14 | AA17: =VLOOKUP(Z17,'Tabla Mujeres'!$AD$7:$AE$27,2,FALSE) -> 5 | AB17: =VLOOKUP(Z17,'Tabla Varones'!$AD$7:$AE$27,2,FALSE) -> 4 | AC17: =IF($N$2="F",AA17,AB17) -> 5
A18: 16 | B18: 3 | C18: 32 | D18: 3 | E18: 48 | F18: 1 | G18: 64 | H18: 3 | I18: 80 | J18: 1 | K18: 96 | L18: 1 | M18: 112 | N18: 1 | O18: 128 | P18: 3 | Q18: 144 | R18: 1 | S18: 160 | T18: 3 | Y18: Q4 | Z18: =(IF(H14>0,H14-1))+(IF(L13>0,L13-1))+(IF(L16>0,L16-1))+(IF(P14>0,P14-1))+(IF(D14>0,(D14-3)*-1))+(IF(D16>0,(D16-3)*-1))+(IF(H16>0,(H16-3)*-1))+(IF(P16>0,(P16-3)*-1))+(IF(T13>0,(T13-3)*-1))+(IF(T16>0,(T16-3)*-1)) -> 5 | AA18: =VLOOKUP(Z18,'Tabla Mujeres'!$AF$7:$AG$27,2,FALSE) -> 4 | AB18: =VLOOKUP(Z18,'Tabla Varones'!$AF$7:$AG$27,2,FALSE) -> 6 | AC18: =IF($N$2="F",AA18,AB18) -> 4
B19: 5 | F19: 2 | H19: 1 | J19: 1 | L19: 3 | N19: 2 | P19: 1 | Y19: MI | Z19: =(IF(B18>0,B18-1))+(IF(D9>0,D9-1))+(IF(F18>0,F18-1))+(IF(H12>0,H12-1))+(IF(J13>0,J13-1))+(IF(L7>0,L7-1))+(IF(L17>0,L17-1))+(IF(N7>0,N7-1))+(IF(P5>0,P5-1))+(IF(R18>0,R18-1))+(IF(F4>0,F4-1))+(IF(T11>0,(T11-3)*-1)) -> 8 | AC19: =VLOOKUP(Z19,'Estilo de Respuesta'!B5:C29,2,FALSE) -> 4
B20: 3 | D20: 3 | F20: 2 | H20: 1 | L20: 1 | N20: 2 | P20: 3 | Y20: IN | Z20: =(IF(B7=2,1))+(IF(B10=2,1))+(IF(B12=2,1))+(IF(B16=2,1))+(IF(B18=2,1))+(IF(D8=2,1))+(IF(D10=2,1))+(IF(D12=2,1))+(IF(D13=2,1))+(IF(D14=2,1))+(IF(F5=2,1))+(IF(F6=2,1))+(IF(H5=2,1))+(IF(H10=2,1))+(IF(H17=2,1))+(IF(J13=2,1))+(IF(J18=2,1))+(IF(L7=2,1))+(IF(L12=2,1))+(IF(L13=2,1))+(IF(L14=2,1))+(IF(N4=2,1))+(IF(N7=2,1))+(IF(N8=2,1))+(IF(N17=2,1))+(IF(P6=2,1))+(IF(P11=2,1))+(IF(P13=2,1))+(IF(P15=2,1))+(IF(P18=2,1))+(IF(R4=2,1))+(IF(R5=2,1))+(IF(R14=2,1))+(IF(R18=2,1))+(IF(T9=2,1))+(IF(T12=2,1))+(IF(T16=2,1))+(IF(T18=2,1)) -> 1 | AC20: =VLOOKUP(Z20,'Estilo de Respuesta'!D5:E43,2,FALSE) -> 7
B21: 3 | D21: 1 | F21: 11 | H21: 3 | L21: 3 | N21: 2 | W21: =(IF(B4=1,1))+(IF(B6=1,1))+(IF(B7=1,1))+(IF(B8=1,1))+(IF(B11=1,1))+(IF(B12=1,1))+(IF(B14=1,1))+(IF(B15=1,1))+(IF(B16=1,1))+(IF(D9=1,1))+(IF(D13=1,1))+(IF(D14=1,1))+(IF(D15=1,1))+(IF(F3=1,1))+(IF(F4=1,1))+(IF(F5=1,1))+(IF(F6=1,1))+(IF(F9=1,1))+(IF(F10=1,1))+(IF(F11=1,1))+(IF(F13=1,1))+(IF(F14=1,1))+(IF(F17=1,1))+(IF(F18=1,1))+(IF(H3=1,1))+(IF(H4=1,1))+(IF(H8=1,1))+(IF(H11=1,1))+(IF(H12=1,1))+(IF(H13=1,1))+(IF(H15=1,1))+(IF(H16=1,1))+(IF(H17=1,1))+(IF(H18=1,1))+(IF(J3=1,1))+(IF(J4=1,1))+(IF(J6=1,1))+(IF(J7=1,1))+(IF(J9=1,1))+(IF(J14=1,1))+(IF(J15=1,1))+(IF(J17=1,1))+(IF(L5=1,1))+(IF(L7=1,1))+(IF(L9=1,1))+(IF(L11=1,1))+(IF(L12=1,1))+(IF(L13=1,1))+(IF(L14=1,1))+(IF(L15=1,1))+(IF(L18=1,1))+(IF(N3=1,1))+(IF(N5=1,1)) -> 34 | X21: =(IF(N6=1,1))+(IF(N9=1,1))+(IF(N11=1,1))+(IF(N12=1,1))+(IF(N13=1,1))+(IF(N14=1,1))+(IF(N16=1,1))+(IF(N17=1,1))+(IF(P3=1,1))+(IF(P4=1,1))+(IF(P6=1,1))+(IF(P7=1,1))+(IF(P8=1,1))+(IF(P14=1,1))+(IF(P15=1,1))+(IF(P16=1,1))+(IF(P18=1,1))+(IF(R4=1,1))+(IF(R6=1,1))+(IF(R7=1,1))+(IF(R8=1,1))+(IF(R9=1,1))+(IF(R11=1,1))+(IF(R12=1,1))+(IF(R15=1,1))+(IF(R16=1,1))+(IF(T3=1,1))+(IF(T4=1,1))+(IF(T6=1,1))+(IF(T7=1,1))+(IF(T8=1,1))+(IF(T9=1,1))+(IF(T10=1,1))+(IF(T13=1,1))+(IF(T14=1,1))+(IF(T15=1,1))+(IF(T17=1,1))+(IF(V3=1,1))+(IF(V7=1,1))+(IF(V8=1,1))+(IF(V9=1,1))+(IF(V11=1,1)) -> 27 | Y21: AQ | Z21: =(W21+X21) -> 61 | AC21: =VLOOKUP(Z21,'Estilo de Respuesta'!F5:G82,2,FALSE) -> 8
B22: 3 | D22: 3 | F22: 2 | L22: 2 | N22: 1
F23: 3
F24: 2
A84: F
A85: M

Sheet Resultados
E1: OBTENCIÓN DE DIMENSIONES GLOBALES
B3: NOMBRE: | C3: ='Ingreso Datos'!D2 -> aabr | J3: FECHA: | L3: ='Ingreso Datos'!U2 -> 44792
E5: ESTABILIDAD | G5: ANSIEDAD | I5: DUREZA | K5: INDEPENDENCIA | M5: AUTOCONTROL
B6: ESCALAS PRIMARIAS | C6: PD | D6: DE | E6: + | F6: -- | G6: + | H6: -- | I6: + | J6: -- | K6: + | L6: -- | M6: + | N6: -- | R6: ='Ingreso Datos'!AC18 -> 4
A7: A | B7: Afabilidad | C7: ='Ingreso Datos'!Z3 -> 16 | D7: ='Ingreso Datos'!$AC3 -> 5 | E7: =$D7*5 -> 25 | G7: =D7*2 -> 10 | J7: =$D7*2 -> 10 | L7: =$D7*1 -> 5 | M7: =$D7*3 -> 15 | P7: ESTILOS DE | R7: ='Ingreso Datos'!AC17 -> 5
A8: B | B8: Razonamiento | C8: ='Ingreso Datos'!Z4 -> 7 | D8: ='Ingreso Datos'!$AC4 -> 3 | E8: =D8*1 -> 3 | G8: =D8*2 -> 6 | J8: =$D8*1 -> 3 | K8: =$D8*1 -> 3 | P8: RESPUESTA | R8: ='Ingreso Datos'!AC16 -> 9
A9: C | B9: Estabilidad | C9: ='Ingreso Datos'!Z5 -> 10 | D9: ='Ingreso Datos'!$AC5 -> 4 | F9: =D9*1 -> 4 | H9: =$D9*3 -> 12 | J9: =$D9*1 -> 4 | K9: =$D9*1 -> 4 | N9: =$D9*1 -> 4 | P9: MI | R9: ='Ingreso Datos'!AC15 -> 5
A10: E | B10: Dominancia | C10: ='Ingreso Datos'!Z6 -> 8 | D10: ='Ingreso Datos'!$AC6 -> 3 | G10: =D10*1 -> 3 | J10: =$D10*1 -> 3 | K10: =$D10*7 -> 21 | M10: =$D10*1 -> 3 | P10: PD: | Q10: ='Ingreso Datos'!Z19 -> 8 | R10: ='Ingreso Datos'!AC14 -> 6
A11: F | B11: Animación | C11: ='Ingreso Datos'!Z7 -> 10 | D11: ='Ingreso Datos'!$AC7 -> 4 | E11: =D11*3 -> 12 | G11: =D11*1 -> 4 | I11: =$D11*3 -> 12 | K11: =$D11*3 -> 12 | N11: =$D11*3 -> 12 | P11: DE: | Q11: ='Ingreso Datos'!AC19 -> 4 | R11: ='Ingreso Datos'!AC13 -> 6
A12: G | B12: Atención-normas | C12: ='Ingreso Datos'!Z8 -> 20 | D12: ='Ingreso Datos'!$AC8 -> 8 | E12: =D12*1 -> 8 | G12: =D12*1 -> 8 | L12: =$D12*1 -> 8 | M12: =$D12*5 -> 40 | R12: ='Ingreso Datos'!AC12 -> 7
A13: H | B13: Atrevimiento | C13: ='Ingreso Datos'!Z9 -> 2 | D13: ='Ingreso Datos'!$AC9 -> 3 | E13: =D13*1 -> 3 | H13: =$D13*2 -> 6 | J13: =$D13*2 -> 6 | K13: =$D13*2 -> 6 | N13: =$D13*1 -> 3 | R13: ='Ingreso Datos'!AC11 -> 7
A14: I | B14: Sensibilidad | C14: ='Ingreso Datos'!Z10 -> 9 | D14: ='Ingreso Datos'!$AC10 -> 4 | E14: =D14*2 -> 8 | G14: =D14*1 -> 4 | J14: =$D14*3 -> 12 | L14: =$D14*2 -> 8 | M14: =$D14*1 -> 4 | P14: IN | R14: ='Ingreso Datos'!AC10 -> 4
A15: L | B15: Vigilancia | C15: ='Ingreso Datos'!Z11 -> 16 | D15: ='Ingreso Datos'!$AC11 -> 7 | G15: =D15*3 -> 21 | I15: =$D15*2 -> 14 | K15: =$D15*3 -> 21 | P15: PD: | Q15: ='Ingreso Datos'!Z20 -> 1 | R15: ='Ingreso Datos'!AC9 -> 3
A16: M | B16: Abstracción | C16: ='Ingreso Datos'!Z12 -> 12 | D16: ='Ingreso Datos'!$AC12 -> 7 | J16: =$D16*3 -> 21 | N16: =$D16*1 -> 7 | P16: DE: | Q16: ='Ingreso Datos'!AC20 -> 7 | R16: ='Ingreso Datos'!AC8 -> 8
A17: N | B17: Privacidad | C17: ='Ingreso Datos'!Z13 -> 12 | D17: ='Ingreso Datos'!$AC13 -> 6 | F17: =D17*3 -> 18 | G17: =D17*1 -> 6 | I17: =$D17*1 -> 6 | K17: =$D17*2 -> 12 | R17: ='Ingreso Datos'!AC7 -> 4
A18: O | B18: Aprensión | C18: ='Ingreso Datos'!Z14 -> 14 | D18: ='Ingreso Datos'!$AC14 -> 6 | E18: =D18*2 -> 12 | G18: =D18*5 -> 30 | I18: =$D18*1 -> 6 | M18: =$D18*3 -> 18 | R18: ='Ingreso Datos'!AC6 -> 3
A19: Q1 | B19: Apertura-cambio | C19: ='Ingreso Datos'!Z15 -> 15 | D19: ='Ingreso Datos'!$AC15 -> 5 | F19: =D19*2 -> 10 | H19: =$D19*4 -> 20 | J19: =$D19*8 -> 40 | K19: =$D19*1 -> 5 | P19: AQ | R19: ='Ingreso Datos'!AC5 -> 4
A20: Q2 | B20: Autosuficiencia | C20: ='Ingreso Datos'!Z16 -> 14 | D20: ='Ingreso Datos'!$AC16 -> 9 | F20: =D20*4 -> 36 | H20: =$D20*2 -> 18 | J20: =$D20*3 -> 27 | P20: PD: | Q20: ='Ingreso Datos'!Z21 -> 61 | R20: ='Ingreso Datos'!AC4 -> 3
A21: Q3 | B21: Perfeccionismo | C21: ='Ingreso Datos'!Z17 -> 14 | D21: ='Ingreso Datos'!$AC17 -> 5 | E21: =D21*1 -> 5 | G21: =D21*3 -> 15 | J21: =$D21*1 -> 5 | K21: =$D21*1 -> 5 | M21: =$D21*7 -> 35 | P21: DE: | Q21: ='Ingreso Datos'!AC21 -> 8 | R21: ='Ingreso Datos'!AC3 -> 5
A22: Q4 | B22: Tensión | C22: ='Ingreso Datos'!Z18 -> 5 | D22: ='Ingreso Datos'!$AC18 -> 4 | E22: =D22*1 -> 4 | G22: =D22*4 -> 16 | I22: =$D22*3 -> 12 | K22: =$D22*2 -> 8 | R22: =Q11 -> 4
C23: Constantes | E23: 16 | H23: 16 | I23: 138 | L23: 50 | N23: 22 | R23: =M25 -> 6.7
C24: Sumas | E24: =SUM(E7:E23) -> 96 | F24: =SUM(F7:F23) -> 68 | G24: =SUM(G7:G23) -> 123 | H24: =SUM(H7:H23) -> 72 | I24: =SUM(I7:I23) -> 188 | J24: =SUM(J7:J23) -> 131 | K24: =SUM(K7:K23) -> 97 | L24: =SUM(L7:L23) -> 71 | ... N24: =SUM(N7:N23) -> 48 | R24: =K25 -> 2.6
B25: Decatipo en la dimensión | E25: =ABS((E24-F24)/10) -> 2.8 | G25: =ABS((G24-H24)/10) -> 5.1 | I25: =ABS((I24-J24)/10) -> 5.7 | K25: =ABS((K24-L24)/10) -> 2.6 | M25: =ABS((M24-N24)/10) -> 6.7 | R25: =I25 -> 5.7
R26: =G25 -> 5.1
R27: =E25 -> 2.8
E28: PERFIL DE ESCALAS PRIMARIAS Y DIMESIONES GLOBALES
B30: NOMBRE: | C30: ='Ingreso Datos'!D2 -> aabr | J30: FECHA: | L30: ='Ingreso Datos'!U2 -> 44792
B32: ESCALAS PRIMARIAS | C32: DE | D32: El ptje bajo define una persona... | I32: 1 | J32: 2 | K32: 3 | L32: 4 | M32: 5 | N32: 6 | O32: 7 | P32: 8 | Q32: 9 | R32: 10 | S32: El ptje alto define una persona...
A33: A | B33: Afabilidad | C33: ='Ingreso Datos'!$AC3 -> 5 | D33: Fría, impersonal, distante | S33: Cálida, afable, generosa, atenta a los demás | V33: A
A34: B | B34: Razonamiento | C34: ='Ingreso Datos'!$AC4 -> 3 | D34: De pensamiento concreto | S34: De pensamiento abstracto | V34: B
A35: C | B35: Estabilidad | C35: ='Ingreso Datos'!$AC5 -> 4 | D35: Reactiva, emocionalmente cambiante | S35: Emocionalmente estable, adaptada, madura | V35: C
A36: E | B36: Dominancia | C36: ='Ingreso Datos'!$AC6 -> 3 | D36: Deferente, cooperadora, que evita conflictos | S36: Dominante, asertiva, competitiva | V36: E
A37: F | B37: Animación | C37: ='Ingreso Datos'!$AC7 -> 4 | D37: Seria, reprimida, cuidadosa | S37: Animosa, espontánea, activa, entusiasta | V37: F
A38: G | B38: Atención-normas | C38: ='Ingreso Datos'!$AC8 -> 8 | D38: Inconformista, muy suya, indulgente | S38: Atenta a las normas, cumplidora, formal | V38: G
A39: H | B39: Atrevimiento | C39: ='Ingreso Datos'!$AC9 -> 3 | D39: Tímida, temerosa, cohibida | S39: Emprendedora, atrevida y segura en lo social | V39: H
A40: I | B40: Sensibilidad | C40: ='Ingreso Datos'!$AC10 -> 4 | D40: Objetiva, nada sentimental, utilitaria | S40: Sensible, esteta, sentimental | V40: I
A41: L | B41: Vigilancia | C41: ='Ingreso Datos'!$AC11 -> 7 | D41: Confiada, sin sospechas, adaptable | S41: Vigilante, suspicaz, escéptica, precavida | V41: L
A42: M | B42: Abstracción | C42: ='Ingreso Datos'!$AC12 -> 7 | D42: Práctica, con los pies en tierra, realista | S42: Abstraida, imaginativa, idealista | V42: M
A43: N | B43: Privacidad | C43: ='Ingreso Datos'!$AC13 -> 6 | D43: Abierta, genuina, llana, natural | S43: Privada, calculadora, discreta, que no se abre | V43: N
A44: O | B44: Aprensión | C44: ='Ingreso Datos'!$AC14 -> 6 | D44: Segura, despreocupada, satisfecha | S44: Aprensiva, insegura, preocupada | V44: O
...

Sheet Tabla Mujeres
A4: DECAPITOS
A6: Esc. | B6: A | D6: B | F6: C | H6: E | J6: F | L6: G | N6: H | P6: I | R6: L | T6: M | V6: N | X6: O | Z6: Q1 | AB6: Q2 | AD6: Q3 | AF6: Q4
B7: 0 | C7: 1 | D7: 0 | E7: 1 | F7: 0 | G7: 1 | H7: 0 | I7: 1 | J7: 0 | K7: 1 | L7: 0 | M7: 1 | N7: 0 | O7: 2 | P7: 0 | Q7: 1 | R7: 0 | S7: 1 | T7: 0 | U7: 3 | V7: 0 | W7: 1 | X7: 0 | Y7: 2 | Z7: 0 | AA7: 1 | AB7: 0 | AC7: 3 | AD7: 0 | AE7: 1 | AF7: 0 | AG7: 2
B8: 1 | C8: 1 | D8: 1 | E8: 1 | F8: 1 | G8: 1 | H8: 1 | I8: 1 | J8: 1 | K8: 1 | L8: 1 | M8: 1 | N8: 1 | O8: 2 | P8: 1 | Q8: 1 | R8: 1 | S8: 2 | T8: 1 | U8: 4 | V8: 1 | W8: 2 | X8: 1 | Y8: 3 | Z8: 1 | AA8: 1 | AB8: 1 | AC8: 4 | AD8: 1 | AE8: 1 | AF8: 1 | AG8: 3
B9: 2 | C9: 1 | D9: 2 | E9: 1 | F9: 2 | G9: 2 | H9: 2 | I9: 1 | J9: 2 | K9: 1 | L9: 2 | M9: 1 | N9: 2 | O9: 3 | P9: 2 | Q9: 1 | R9: 2 | S9: 2 | T9: 2 | U9: 4 | V9: 2 | W9: 2 | X9: 2 | Y9: 3 | Z9: 2 | AA9: 1 | AB9: 2 | AC9: 4 | AD9: 2 | AE9: 1 | AF9: 2 | AG9: 3
B10: 3 | C10: 1 | D10: 3 | E10: 1 | F10: 3 | G10: 2 | H10: 3 | I10: 1 | J10: 3 | K10: 1 | L10: 3 | M10: 1 | N10: 3 | O10: 3 | P10: 3 | Q10: 2 | R10: 3 | S10: 3 | T10: 3 | U10: 4 | V10: 3 | W10: 3 | X10: 3 | Y10: 3 | Z10: 3 | AA10: 1 | AB10: 3 | AC10: 6 | AD10: 3 | AE10: 2 | AF10: 3 | AG10: 4
B11: 4 | C11: 1 | D11: 4 | E11: 1 | F11: 4 | G11: 3 | H11: 4 | I11: 1 | J11: 4 | K11: 1 | L11: 4 | M11: 2 | N11: 4 | O11: 4 | P11: 4 | Q11: 2 | R11: 4 | S11: 3 | T11: 4 | U11: 4 | V11: 4 | W11: 3 | X11: 4 | Y11: 4 | Z11: 4 | AA11: 1 | AB11: 4 | AC11: 6 | AD11: 4 | AE11: 2 | AF11: 4 | AG11: 4
B12: 5 | C12: 1 | D12: 5 | E12: 2 | F12: 5 | G12: 3 | H12: 5 | I12: 2 | J12: 5 | K12: 2 | L12: 5 | M12: 3 | N12: 5 | O12: 4 | P12: 5 | Q12: 2 | R12: 5 | S12: 3 | T12: 5 | U12: 4 | V12: 5 | W12: 4 | X12: 5 | Y12: 4 | Z12: 5 | AA12: 2 | AB12: 5 | AC12: 7 | AD12: 5 | AE12: 2 | AF12: 5 | AG12: 4
B13: 6 | C13: 1 | D13: 6 | E13: 3 | F13: 6 | G13: 3 | H13: 6 | I13: 2 | J13: 6 | K13: 2 | L13: 6 | M13: 3 | N13: 6 | O13: 4 | P13: 6 | Q13: 3 | R13: 6 | S13: 4 | T13: 6 | U13: 5 | V13: 6 | W13: 4 | X13: 6 | Y13: 4 | Z13: 6 | AA13: 2 | AB13: 6 | AC13: 7 | AD13: 6 | AE13: 3 | AF13: 6 | AG13: 4
B14: 7 | C14: 2 | D14: 7 | E14: 3 | F14: 7 | G14: 4 | H14: 7 | I14: 2 | J14: 7 | K14: 3 | L14: 7 | M14: 3 | N14: 7 | O14: 4 | P14: 7 | Q14: 3 | R14: 7 | S14: 4 | T14: 7 | U14: 6 | V14: 7 | W14: 4 | X14: 7 | Y14: 4 | Z14: 7 | AA14: 2 | AB14: 7 | AC14: 7 | AD14: 7 | AE14: 3 | AF14: 7 | AG14: 4
B15: 8 | C15: 2 | D15: 8 | E15: 4 | F15: 8 | G15: 4 | H15: 8 | I15: 3 | J15: 8 | K15: 3 | L15: 8 | M15: 4 | N15: 8 | O15: 4 | P15: 8 | Q15: 3 | R15: 8 | S15: 4 | T15: 8 | U15: 6 | V15: 8 | W15: 4 | X15: 8 | Y15: 4 | Z15: 8 | AA15: 3 | AB15: 8 | AC15: 7 | AD15: 8 | AE15: 3 | AF15: 8 | AG15: 4
B16: 9 | C16: 3 | D16: 9 | E16: 4 | F16: 9 | G16: 4 | H16: 9 | I16: 3 | J16: 9 | K16: 3 | L16: 9 | M16: 4 | N16: 9 | O16: 4 | P16: 9 | Q16: 4 | R16: 9 | S16: 4 | T16: 9 | U16: 6 | V16: 9 | W16: 5 | X16: 9 | Y16: 4 | Z16: 9 | AA16: 3 | AB16: 9 | AC16: 8 | AD16: 9 | AE16: 4 | AF16: 9 | AG16: 5
B17: 10 | C17: 3 | D17: 10 | E17: 6 | F17: 10 | G17: 4 | H17: 10 | I17: 4 | J17: 10 | K17: 4 | L17: 10 | M17: 4 | N17: 10 | O17: 4 | P17: 10 | Q17: 4 | R17: 10 | S17: 5 | T17: 10 | U17: 6 | V17: 10 | W17: 6 | X17: 10 | Y17: 4 | Z17: 10 | AA17: 3 | AB17: 10 | AC17: 8 | AD17: 10 | AE17: 4 | AF17: 10 | AG17: 6
B18: 11 | C18: 3 | D18: 11 | E18: 7 | F18: 11 | G18: 4 | H18: 11 | I18: 4 | J18: 11 | K18: 4 | L18: 11 | M18: 4 | N18: 11 | O18: 4 | P18: 11 | Q18: 4 | R18: 11 | S18: 5 | T18: 11 | U18: 7 | V18: 11 | W18: 6 | X18: 11 | Y18: 5 | Z18: 11 | AA18: 4 | AB18: 11 | AC18: 8 | AD18: 11 | AE18: 4 | AF18: 11 | AG18: 6
... B22: 15 | C22: 4 | D22: 15 | E22: 10 | F22: 15 | G22: 6 | H22: 15 | I22: 6 | J22: 15 | K22: 5 | L22: 15 | M22: 6 | N22: 15 | O22: 6 | P22: 15 | Q22: 5 | R22: 15 | S22: 7 | T22: 15 | U22: 8 | V22: 15 | W22: 7 | X22: 15 | Y22: 6 | Z22: 15 | AA22: 5 | AB22: 15 | AC22: 9 | AD22: 15 | AE22: 6 | AF22: 15 | AG22: 7
B23: 16 | C23: 5 | F23: 16 | G23: 6 | H23: 16 | I23: 7 | J23: 16 | K23: 6 | L23: 16 | M23: 7 | N23: 16 | O23: 6 | P23: 16 | Q23: 6 | R23: 16 | S23: 7 | T23: 16 | U23: 8 | V23: 16 | W23: 7 | X23: 16 | Y23: 6 | Z23: 16 | AA23: 6 | AB23: 16 | AC23: 10 | AD23: 16 | AE23: 6 | AF23: 16 | AG23: 8
B24: 17 | C24: 6 | F24: 17 | G24: 7 | H24: 17 | I24: 7 | J24: 17 | K24: 7 | L24: 17 | M24: 7 | N24: 17 | O24: 6 | P24: 17 | Q24: 6 | R24: 17 | S24: 8 | T24: 17 | U24: 8 | V24: 17 | W24: 8 | X24: 17 | Y24: 7 | Z24: 17 | AA24: 6 | AB24: 17 | AC24: 10 | AD24: 17 | AE24: 7 | AF24: 17 | AG24: 8
B25: 18 | C25: 6 | F25: 18 | G25: 7 | H25: 18 | I25: 8 | J25: 18 | K25: 7 | L25: 18 | M25: 7 | N25: 18 | O25: 7 | P25: 18 | Q25: 6 | R25: 18 | S25: 8 | T25: 18 | U25: 9 | V25: 18 | W25: 8 | X25: 18 | Y25: 7 | Z25: 18 | AA25: 6 | AB25: 18 | AC25: 10 | AD25: 18 | AE25: 7 | AF25: 18 | AG25: 9
B26: 19 | C26: 7 | F26: 19 | G26: 8 | H26: 19 | I26: 9 | J26: 19 | K26: 8 | L26: 19 | M26: 8 | N26: 19 | O26: 7 | P26: 19 | Q26: 7 | R26: 19 | S26: 9 | T26: 19 | U26: 9 | V26: 19 | W26: 9 | X26: 19 | Y26: 8 | Z26: 19 | AA26: 7 | AB26: 19 | AC26: 10 | AD26: 19 | AE26: 8 | AF26: 19 | AG26: 9
B27: 20 | C27: 8 | F27: 20 | G27: 9 | H27: 20 | I27: 10 | J27: 20 | K27: 9 | L27: 20 | M27: 8 | N27: 20 | O27: 8 | P27: 20 | Q27: 8 | R27: 20 | S27: 10 | T27: 20 | U27: 10 | V27: 20 | W27: 10 | X27: 20 | Y27: 9 | Z27: 20 | AA27: 7 | AB27: 20 | AC27: 10 | AD27: 20 | AE27: 9 | AF27: 20 | AG27: 10
B28: 21 | C28: 8 | L28: 21 | M28: 9 | P28: 21 | Q28: 8 | T28: 21 | U28: 10 | Z28: 21 | AA28: 8
B29: 22 | C29: 9 | L29: 22 | M29: 10 | P29: 22 | Q29: 9 | T29: 22 | U29: 10 | Z29: 22 | AA29: 8
Z30: 23 | AA30: 8
Z31: 24 | AA31: 9
Z32: 25 | AA32: 10
Z33: 26 | AA33: 10
Z34: 27 | AA34: 10
Z35: 28 | AA35: 10

Sheet Tabla Varones
A4: DECAPITOS
A6: Esc. | B6: A | D6: B | F6: C | H6: E | J6: F | L6: G | N6: H | P6: I | R6: L | T6: M | V6: N | X6: O | Z6: Q1 | AB6: Q2 | AD6: Q3 | AF6: Q4
B7: 0 | C7: 1 | D7: 0 | E7: 1 | F7: 0 | G7: 1 | H7: 0 | I7: 1 | J7: 0 | K7: 1 | L7: 0 | M7: 1 | N7: 0 | O7: 1 | P7: 0 | Q7: 1 | R7: 0 | S7: 2 | T7: 0 | U7: 3 | V7: 0 | W7: 1 | X7: 0 | Y7: 3 | Z7: 0 | AA7: 1 | AB7: 0 | AC7: 3 | AD7: 0 | AE7: 1 | AF7: 0 | AG7: 3
B8: 1 | C8: 1 | D8: 1 | E8: 1 | F8: 1 | G8: 1 | H8: 1 | I8: 1 | J8: 1 | K8: 1 | L8: 1 | M8: 1 | N8: 1 | O8: 2 | P8: 1 | Q8: 2 | R8: 1 | S8: 3 | T8: 1 | U8: 4 | V8: 1 | W8: 2 | X8: 1 | Y8: 4 | Z8: 1 | AA8: 1 | AB8: 1 | AC8: 4 | AD8: 1 | AE8: 1 | AF8: 1 | AG8: 4
B9: 2 | C9: 1 | D9: 2 | E9: 1 | F9: 2 | G9: 1 | H9: 2 | I9: 1 | J9: 2 | K9: 1 | L9: 2 | M9: 1 | N9: 2 | O9: 2 | P9: 2 | Q9: 3 | R9: 2 | S9: 3 | T9: 2 | U9: 4 | V9: 2 | W9: 3 | X9: 2 | Y9: 4 | Z9: 2 | AA9: 1 | AB9: 2 | AC9: 5 | AD9: 2 | AE9: 1 | AF9: 2 | AG9: 4
B10: 3 | C10: 1 | D10: 3 | E10: 1 | F10: 3 | G10: 1 | H10: 3 | I10: 1 | J10: 3 | K10: 1 | L10: 3 | M10: 1 | N10: 3 | O10: 2 | P10: 3 | Q10: 3 | R10: 3 | S10: 4 | T10: 3 | U10: 6 | V10: 3 | W10: 3 | X10: 3 | Y10: 4 | Z10: 3 | AA10: 1 | AB10: 3 | AC10: 6 | AD10: 3 | AE10: 1 | AF10: 3 | AG10: 4
B11: 4 | C11: 1 | D11: 4 | E11: 2 | F11: 4 | G11: 2 | H11: 4 | I11: 1 | J11: 4 | K11: 2 | L11: 4 | M11: 2 | N11: 4 | O11: 3 | P11: 4 | Q11: 4 | R11: 4 | S11: 4 | T11: 4 | U11: 6 | V11: 4 | W11: 4 | X11: 4 | Y11: 4 | Z11: 4 | AA11: 2 | AB11: 4 | AC11: 6 | AD11: 4 | AE11: 2 | AF11: 4 | AG11: 5
B12: 5 | C12: 2 | D12: 5 | E12: 2 | F12: 5 | G12: 2 | H12: 5 | I12: 1 | J12: 5 | K12: 2 | L12: 5 | M12: 2 | N12: 5 | O12: 3 | P12: 5 | Q12: 4 | R12: 5 | S12: 4 | T12: 5 | U12: 6 | V12: 5 | W12: 4 | X12: 5 | Y12: 4 | Z12: 5 | AA12: 2 | AB12: 5 | AC12: 7 | AD12: 5 | AE12: 2 | AF12: 5 | AG12: 6
B13: 6 | C13: 2 | D13: 6 | E13: 3 | F13: 6 | G13: 2 | H13: 6 | I13: 2 | J13: 6 | K13: 2 | L13: 6 | M13: 2 | N13: 6 | O13: 3 | P13: 6 | Q13: 5 | R13: 6 | S13: 4 | T13: 6 | U13: 6 | V13: 6 | W13: 4 | X13: 6 | Y13: 5 | Z13: 6 | AA13: 3 | AB13: 6 | AC13: 7 | AD13: 6 | AE13: 2 | AF13: 6 | AG13: 6
B14: 7 | C14: 3 | D14: 7 | E14: 4 | F14: 7 | G14: 3 | H14: 7 | I14: 2 | J14: 7 | K14: 3 | L14: 7 | M14: 3 | N14: 7 | O14: 3 | P14: 7 | Q14: 6 | R14: 7 | S14: 5 | T14: 7 | U14: 7 | V14: 7 | W14: 4 | X14: 7 | Y14: 6 | Z14: 7 | AA14: 3 | AB14: 7 | AC14: 7 | AD14: 7 | AE14: 3 | AF14: 7 | AG14: 6
B15: 8 | C15: 3 | D15: 8 | E15: 4 | F15: 8 | G15: 3 | H15: 8 | I15: 2 | J15: 8 | K15: 3 | L15: 8 | M15: 3 | N15: 8 | O15: 4 | P15: 8 | Q15: 6 | R15: 8 | S15: 5 | T15: 8 | U15: 7 | V15: 8 | W15: 5 | X15: 8 | Y15: 6 | Z15: 8 | AA15: 4 | AB15: 8 | AC15: 8 | AD15: 8 | AE15: 3 | AF15: 8 | AG15: 6
B16: 9 | C16: 3 | D16: 9 | E16: 4 | F16: 9 | G16: 3 | H16: 9 | I16: 3 | J16: 9 | K16: 3 | L16: 9 | M16: 3 | N16: 9 | O16: 4 | P16: 9 | Q16: 6 | R16: 9 | S16: 6 | T16: 9 | U16: 7 | V16: 9 | W16: 5 | X16: 9 | Y16: 6 | Z16: 9 | AA16: 4 | AB16: 9 | AC16: 8 | AD16: 9 | AE16: 3 | AF16: 9 | AG16: 7
B17: 10 | C17: 4 | D17: 10 | E17: 6 | F17: 10 | G17: 3 | H17: 10 | I17: 3 | J17: 10 | K17: 4 | L17: 10 | M17: 4 | N17: 10 | O17: 4 | P17: 10 | Q17: 7 | R17: 10 | S17: 6 | T17: 10 | U17: 7 | V17: 10 | W17: 6 | X17: 10 | Y17: 6 | Z17: 10 | AA17: 4 | AB17: 10 | AC17: 8 | AD17: 10 | AE17: 3 | AF17: 10 | AG17: 7
B18: 11 | C18: 4 | D18: 11 | E18: 6 | F18: 11 | G18: 4 | H18: 11 | I18: 3 | J18: 11 | K18: 4 | L18: 11 | M18: 4 | N18: 11 | O18: 4 | P18: 11 | Q18: 7 | R18: 11 | S18: 6 | T18: 11 | U18: 8 | V18: 11 | W18: 6 | X18: 11 | Y18: 6 | Z18: 11 | AA18: 4 | AB18: 11 | AC18: 8 | AD18: 11 | AE18: 4 | AF18: 11 | AG18: 7
... B22: 15 | C22: 6 | D22: 15 | E22: 10 | F22: 15 | G22: 4 | H22: 15 | I22: 5 | J22: 15 | K22: 6 | L22: 15 | M22: 5 | N22: 15 | O22: 5 | P22: 15 | Q22: 9 | R22: 15 | S22: 8 | T22: 15 | U22: 9 | V22: 15 | W22: 7 | X22: 15 | Y22: 8 | Z22: 15 | AA22: 6 | AB22: 15 | AC22: 10 | AD22: 15 | AE22: 4 | AF22: 15 | AG22: 8
B23: 16 | C23: 6 | F23: 16 | G23: 4 | H23: 16 | I23: 6 | J23: 16 | K23: 6 | L23: 16 | M23: 5 | N23: 16 | O23: 5 | P23: 16 | Q23: 9 | R23: 16 | S23: 8 | T23: 16 | U23: 9 | V23: 16 | W23: 8 | X23: 16 | Y23: 8 | Z23: 16 | AA23: 7 | AB23: 16 | AC23: 10 | AD23: 16 | AE23: 5 | AF23: 16 | AG23: 9
B24: 17 | C24: 6 | F24: 17 | G24: 5 | H24: 17 | I24: 7 | J24: 17 | K24: 7 | L24: 17 | M24: 6 | N24: 17 | O24: 6 | P24: 17 | Q24: 9 | R24: 17 | S24: 9 | T24: 17 | U24: 9 | V24: 17 | W24: 8 | X24: 17 | Y24: 8 | Z24: 17 | AA24: 7 | AB24: 17 | AC24: 10 | AD24: 17 | AE24: 6 | AF24: 17 | AG24: 9
B25: 18 | C25: 7 | F25: 18 | G25: 6 | H25: 18 | I25: 7 | J25: 18 | K25: 8 | L25: 18 | M25: 6 | N25: 18 | O25: 6 | P25: 18 | Q25: 10 | R25: 18 | S25: 9 | T25: 18 | U25: 10 | V25: 18 | W25: 9 | X25: 18 | Y25: 9 | Z25: 18 | AA25: 7 | AB25: 18 | AC25: 10 | AD25: 18 | AE25: 6 | AF25: 18 | AG25: 10
B26: 19 | C26: 7 | F26: 19 | G26: 7 | H26: 19 | I26: 8 | J26: 19 | K26: 9 | L26: 19 | M26: 7 | N26: 19 | O26: 7 | P26: 19 | Q26: 10 | R26: 19 | S26: 10 | T26: 19 | U26: 10 | V26: 19 | W26: 9 | X26: 19 | Y26: 9 | Z26: 19 | AA26: 8 | AB26: 19 | AC26: 10 | AD26: 19 | AE26: 7 | AF26: 19 | AG26: 10
B27: 20 | C27: 8 | F27: 20 | G27: 8 | H27: 20 | I27: 9 | J27: 20 | K27: 10 | L27: 20 | M27: 7 | N27: 20 | O27: 8 | P27: 20 | Q27: 10 | R27: 20 | S27: 10 | T27: 20 | U27: 10 | V27: 20 | W27: 10 | X27: 20 | Y27: 10 | Z27: 20 | AA27: 8 | AB27: 20 | AC27: 10 | AD27: 20 | AE27: 8 | AF27: 20 | AG27: 10
B28: 21 | C28: 9 | L28: 21 | M28: 8 | P28: 21 | Q28: 10 | T28: 21 | U28: 10 | Z28: 21 | AA28: 9
B29: 22 | C29: 10 | L29: 22 | M29: 9 | P29: 22 | Q29: 10 | T29: 22 | U29: 10 | Z29: 22 | AA29: 9
Z30: 23 | AA30: 9
Z31: 24 | AA31: 10
Z32: 25 | AA32: 10
Z33: 26 | AA33: 10
Z34: 27 | AA34: 10
Z35: 28 | AA35: 10

Sheet Estilo de Respuesta
A2: DECATIPOS
A4: Esc. | B4: MI | D4: IN | F4: AQ
B5: 0 | C5: 1 | D5: 0 | E5: 4 | F5: 18 | G5: 1
B6: 1 | C6: 1 | D6: 1 | E6: 7 | F6: 19 | G6: 1
B7: 2 | C7: 1 | D7: 2 | E7: 8 | F7: 20 | G7: 1
B8: 3 | C8: 2 | D8: 3 | E8: 8 | F8: 21 | G8: 1
B9: 4 | C9: 2 | D9: 4 | E9: 9 | F9: 22 | G9: 1
B10: 5 | C10: 3 | D10: 5 | E10: 9 | F10: 23 | G10: 1
B11: 6 | C11: 3 | D11: 6 | E11: 9 | F11: 24 | G11: 1
B12: 7 | C12: 3 | D12: 7 | E12: 9 | F12: 25 | G12: 1
B13: 8 | C13: 4 | D13: 8 | E13: 10 | F13: 26 | G13: 1
B14: 9 | C14: 4 | D14: 9 | E14: 10 | F14: 27 | G14: 1
B15: 10 | C15: 4 | D15: 10 | E15: 10 | F15: 28 | G15: 1
B16: 11 | C16: 4 | D16: 11 | E16: 10 | F16: 29 | G16: 1
... B29: 24 | C29: 10 | D29: 24 | E29: 10 | F29: 42 | G29: 4
D30: 25 | E30: 10 | F30: 43 | G30: 4
D31: 26 | E31: 10 | F31: 44 | G31: 4
D32: 27 | E32: 10 | F32: 45 | G32: 4
D33: 28 | E33: 10 | F33: 46 | G33: 4
D34: 29 | E34: 10 | F34: 47 | G34: 5
D35: 30 | E35: 10 | F35: 48 | G35: 5
D36: 31 | E36: 10 | F36: 49 | G36: 6
D37: 32 | E37: 10 | F37: 50 | G37: 6
D38: 33 | E38: 10 | F38: 51 | G38: 6
D39: 34 | E39: 10 | F39: 52 | G39: 6
D40: 35 | E40: 10 | F40: 53 | G40: 6
D41: 36 | E41: 10 | F41: 54 | G41: 7
... D43: 38 | E43: 10 | F43: 56 | G43: 7
F44: 57 | G44: 7
F45: 58 | G45: 7
F46: 59 | G46: 8
F47: 60 | G47: 8
F48: 61 | G48: 8
F49: 62 | G49: 8
F50: 63 | G50: 9
F51: 64 | G51: 9
F52: 65 | G52: 9
F53: 66 | G53: 9
F54: 67 | G54: 9
F55: 68 | G55: 10
...
